<?xml version="1.0" encoding="utf-8"?>
<!-- =================================================================================== -->
<!-- |    This document was autogenerated by xacro from mocca.xacro                    | -->
<!-- |    EDITING THIS FILE BY HAND IS NOT RECOMMENDED                                 | -->
<!-- =================================================================================== -->
<robot name="mocca">
  <material name="Brown">
    <color rgba="0.4823 0.3843 0.2666 1"/>
  </material>
  <material name="DarkBrown">
    <color rgba="0.1843 0.1176 0.0784 1"/>
  </material>
  <link name="base_link">
    <visual>
      <geometry>
        <mesh filename="file:///home/parallels/catkin_ws/src/mocca_description/meshes/MC_BD_Cover.stl" scale="0.001 0.001 0.001"/>
      </geometry>
      <origin rpy="0 0 1.57" xyz="0.03 0 0.005"/>
      <material name="Brown"/>
    </visual>
  </link>
  <joint name="joint_body_panelF" type="fixed">
    <parent link="base_link"/>
    <child link="link_body_panelF"/>
    <origin xyz="0 0 0"/>
  </joint>
  <link name="link_body_panelF">
    <visual>
      <geometry>
        <mesh filename="file:///home/parallels/catkin_ws/src/mocca_description/meshes/MC_BD_FrontPanel.stl" scale="0.001 0.001 0.001"/>
      </geometry>
      <origin rpy="0 0 1.57" xyz="0.08 0 0.015"/>
      <material name="DarkBrown"/>
    </visual>
  </link>
  <!-- NECK START-->
  <joint name="joint_head_yaw" type="revolute">
    <parent link="base_link"/>
    <child link="link_neck_yaw"/>
    <axis rpy="0 0 0" xyz="0 0 1"/>
    <origin rpy="0 0 0" xyz="-0.02 0 0.195"/>
    <limit effort="1000.0" lower="-1.57" upper="1.57" velocity="0.5"/>
  </joint>
  <link name="link_neck_yaw">
    <visual>
      <geometry>
        <mesh filename="file:///home/parallels/catkin_ws/src/mocca_description/meshes/MC_NECK_Base.stl" scale="0.001 0.001 0.001"/>
      </geometry>
      <origin rpy="0 0 1.57" xyz="0 0 0"/>
      <material name="DarkBrown"/>
    </visual>
  </link>
  <joint name="joint_neck_lower" type="fixed">
    <parent link="link_neck_yaw"/>
    <child link="link_neck_lower"/>
    <origin xyz="0 0 0"/>
  </joint>
  <link name="link_neck_lower">
    <visual>
      <geometry>
        <mesh filename="file:///home/parallels/catkin_ws/src/mocca_description/meshes/MC_NECK_Lower.stl" scale="0.001 0.001 0.001"/>
      </geometry>
      <origin rpy="0 0 1.57" xyz="0 0 0"/>
      <material name="DarkBrown"/>
    </visual>
  </link>
  <joint name="joint_neck_upper" type="fixed">
    <parent link="link_neck_lower"/>
    <child link="link_neck_upper"/>
    <origin xyz="0.015 0 0.02"/>
  </joint>
  <link name="link_neck_upper">
    <visual>
      <geometry>
        <mesh filename="file:///home/parallels/catkin_ws/src/mocca_description/meshes/MC_NECK_Upper.stl" scale="0.001 0.001 0.001"/>
      </geometry>
      <origin rpy="0 0 1.57" xyz="0 0 0"/>
      <material name="DarkBrown"/>
    </visual>
  </link>
  <joint name="joint_head_pitch" type="revolute">
    <parent link="link_neck_upper"/>
    <child link="link_head_pitch"/>
    <axis xyz="0 1 0"/>
    <origin rpy="0 0 0" xyz="0 0 0"/>
    <limit effort="1000.0" lower="-1.57" upper="1.57" velocity="0.5"/>
  </joint>
  <link name="link_head_pitch">
    <visual>
      <geometry>
        <mesh filename="file:///home/parallels/catkin_ws/src/mocca_description/meshes//MC_HEAD_Base.stl" scale="0.001 0.001 0.001"/>
      </geometry>
      <origin rpy="0 0 1.57" xyz="0 0 0"/>
      <material name="DarkBrown"/>
    </visual>
  </link>
  <joint name="joint_head_plate" type="fixed">
    <parent link="link_head_pitch"/>
    <child link="link_head_plate"/>
    <origin xyz="0 0 0"/>
  </joint>
  <link name="link_head_plate">
    <visual>
      <geometry>
        <mesh filename="file:///home/parallels/catkin_ws/src/mocca_description/meshes/MC_HEAD_Plate.stl" scale="0.001 0.001 0.001"/>
      </geometry>
      <origin rpy="0 0 1.57" xyz="0.02 0 0"/>
      <material name="Brown"/>
    </visual>
  </link>
  <!-- ARM RIGHT START-->
  <joint name="joint_right_1" type="revolute">
    <parent link="base_link"/>
    <child link="link_right_shoulder"/>
    <axis xyz="0 1 0"/>
    <origin xyz="0.013 -0.08 0.14"/>
    <limit effort="1000.0" lower="-1.57" upper="1.57" velocity="0.5"/>
  </joint>
  <link name="link_right_shoulder">
    <visual>
      <geometry>
        <mesh filename="file:///home/parallels/catkin_ws/src/mocca_description/meshes/MC_ARM_Shoulder.stl" scale="0.001 0.001 0.001"/>
      </geometry>
      <origin rpy="0 0 -1.57" xyz="0 -0.03 0"/>
      <material name="DarkBrown"/>
    </visual>
  </link>
  <joint name="joint_right_2" type="revolute">
    <parent link="link_right_shoulder"/>
    <child link="link_right_upper"/>
    <axis xyz="0 0 1"/>
    <origin xyz="0 -0.03 0.0"/>
    <limit effort="1000.0" lower="-1.57" upper="1.57" velocity="0.5"/>
  </joint>
  <link name="link_right_upper">
    <visual>
      <geometry>
        <mesh filename="file:///home/parallels/catkin_ws/src/mocca_description/meshes/MC_ARM_Upper.stl" scale="0.001 0.001 0.001"/>
      </geometry>
      <origin rpy="0 0 0" xyz="0 0 0"/>
      <material name="Brown"/>
    </visual>
  </link>
  <joint name="joint_right_3" type="revolute">
    <parent link="link_right_upper"/>
    <child link="link_right_lower"/>
    <axis xyz="0 0 1"/>
    <origin xyz="0 -0.06 0.0"/>
    <limit effort="1000.0" lower="-1.57" upper="1.57" velocity="0.5"/>
  </joint>
  <link name="link_right_lower">
    <visual>
      <geometry>
        <mesh filename="file:///home/parallels/catkin_ws/src/mocca_description/meshes/MC_ARM_Lower.stl" scale="0.001 0.001 0.001"/>
      </geometry>
      <origin rpy="0 0 0" xyz="0 0 0"/>
      <material name="Brown"/>
    </visual>
  </link>
  <joint name="joint_right_fist" type="fixed">
    <parent link="link_right_lower"/>
    <child link="link_right_fist"/>
    <origin xyz="0 -0.06 0"/>
  </joint>
  <link name="link_right_fist">
    <visual>
      <geometry>
        <mesh filename="file:///home/parallels/catkin_ws/src/mocca_description/meshes/MC_ARM_FistR.stl" scale="0.001 0.001 0.001"/>
      </geometry>
      <origin rpy="0 0 0" xyz="0 0 0"/>
      <material name="DarkBrown"/>
    </visual>
  </link>
  <!-- ARM LEFT START-->
  <joint name="joint_left_1" type="revolute">
    <parent link="base_link"/>
    <child link="link_left_shoulder"/>
    <axis xyz="0 1 0"/>
    <origin xyz="0.013 0.08 0.14"/>
    <limit effort="1000.0" lower="-1.57" upper="1.57" velocity="0.5"/>
  </joint>
  <link name="link_left_shoulder">
    <visual>
      <geometry>
        <mesh filename="file:///home/parallels/catkin_ws/src/mocca_description/meshes/MC_ARM_Shoulder.stl" scale="0.001 0.001 0.001"/>
      </geometry>
      <origin rpy="0 0 1.57" xyz="0 0.03 0"/>
      <material name="DarkBrown"/>
    </visual>
  </link>
  <joint name="joint_left_2" type="revolute">
    <parent link="link_left_shoulder"/>
    <child link="link_left_upper"/>
    <axis xyz="0 0 1"/>
    <origin xyz="0 0.03 0.0"/>
    <limit effort="1000.0" lower="-1.57" upper="1.57" velocity="0.5"/>
  </joint>
  <link name="link_left_upper">
    <visual>
      <geometry>
        <mesh filename="file:///home/parallels/catkin_ws/src/mocca_description/meshes/MC_ARM_Upper.stl" scale="0.001 0.001 0.001"/>
      </geometry>
      <origin rpy="0 0 3.14" xyz="0 0 0"/>
      <material name="Brown"/>
    </visual>
  </link>
  <joint name="joint_left_3" type="revolute">
    <parent link="link_left_upper"/>
    <child link="link_left_lower"/>
    <axis xyz="0 0 1"/>
    <origin xyz="0 0.06 0.0"/>
    <limit effort="1000.0" lower="-1.57" upper="1.57" velocity="0.5"/>
  </joint>
  <link name="link_left_lower">
    <visual>
      <geometry>
        <mesh filename="file:///home/parallels/catkin_ws/src/mocca_description/meshes/MC_ARM_Lower.stl" scale="0.001 0.001 0.001"/>
      </geometry>
      <origin rpy="0 0 3.14" xyz="0 0 0"/>
      <material name="Brown"/>
    </visual>
  </link>
  <joint name="joint_left_fist" type="fixed">
    <parent link="link_left_lower"/>
    <child link="link_left_fist"/>
    <origin xyz="0 0.06 0"/>
  </joint>
  <link name="link_left_fist">
    <visual>
      <geometry>
        <mesh filename="file:///home/parallels/catkin_ws/src/mocca_description/meshes/MC_ARM_FistL.stl" scale="0.001 0.001 0.001"/>
      </geometry>
      <origin rpy="0 0 3.14" xyz="0 0 0"/>
      <material name="DarkBrown"/>
    </visual>
  </link>
</robot>

